scripts/test_case13.txt
40
0 o
1 o
2 o
3 o
4 o
5 o
6 o
7 o
8 o
9 o
10 o
11 o
12 o
13 o
14 o
15 o
16 o
17 o
18 o
19 o
20 o
21 o
22 o
23 o
24 o
25 o
26 o
27 o
28 o
29 o
30 o
31 o
32 o
33 o
34 o
35 o
36 o
37 o
38 o
39 o
.
38 S 58796460 GOOG 31132 3592
37 B 69389474 GOOG 11707 8586
36 S 12549655 AMZN 28977 6182
34 S 2750576 MSFT 15873 2773
39 B 37450440 AAPL 29179 2905
39 B 9579967 AAPL 20864 2558
38 B 87736158 AMZN 62398 712
37 B 42123784 MSFT 34022 8150
39 B 7033862 GOOG 79943 8112
39 S 68538484 MSFT 75127 2718
39 B 28743501 MSFT 49613 6636
37 B 83226596 AAPL 21651 1928
39 S 13629362 MSFT 92972 8199
39 S 83270052 GOOG 6628 7146
37 S 68247028 MSFT 65037 6265
38 C 87736158
39 S 2781313 GOOG 48614 4445
39 B 47488547 AMZN 41655 9719
38 B 44388275 AAPL 33909 5689
39 S 37324707 GOOG 92954 1601
38 C 87736158
37 C 83226596
39 C 83270052
38 S 76504181 MSFT 61691 893
39 S 45603296 AAPL 23044 6861
39 B 20020886 AAPL 45661 287
39 B 98182219 AAPL 82158 5457
39 C 45603296
39 B 47710801 AMZN 18519 5583
39 S 71610439 GOOG 53303 3946
39 S 73220229 AAPL 46610 339
36 S 1674819 AAPL 24862 1543
38 S 85180721 AMZN 9810 5606
38 B 71465126 MSFT 45493 4683
35 S 24835955 AAPL 34983 2523
39 B 92991195 AAPL 23051 9828
36 C 1674819
39 B 54875081 GOOG 85420 3003
38 C 58796460
39 B 24225276 AMZN 85595 9516
39 C 24225276
37 C 68247028
39 C 45603296
39 C 13629362
39 B 45435295 AAPL 88744 449
39 B 73156997 AAPL 40231 5898
37 B 89544980 AAPL 47938 2297
39 B 96986003 GOOG 82559 7199
39 S 69056557 GOOG 82034 511
39 C 68538484
38 C 76504181
39 S 63402477 AMZN 43460 777
39 B 19205361 AMZN 50127 6461
35 S 6874966 MSFT 39860 5708
36 S 1773741 MSFT 86828 3721
39 C 2781313
38 B 44163682 AMZN 29234 8312
39 C 69056557
35 S 56991522 GOOG 60632 9383
39 B 84128311 MSFT 73527 4703
39 B 21312684 GOOG 49365 8648
37 B 95728855 AAPL 15062 5454
39 B 12358975 GOOG 16039 6783
39 B 45651197 AAPL 62185 5374
36 S 43500036 GOOG 56751 1457
37 C 42123784
37 B 32236138 AMZN 80735 7711
35 S 64444103 AMZN 81651 4984
39 B 31282270 AAPL 59321 556
38 B 88066049 AMZN 25552 3468
38 C 58796460
39 B 24869925 MSFT 70486 8932
37 C 68247028
38 S 53447106 AAPL 66151 6216
39 C 45435295
39 B 71527521 AAPL 44321 5849
39 C 45603296
37 C 32236138
38 C 58796460
39 C 21312684
39 C 96986003
38 B 36690675 MSFT 70336 2769
35 B 863922 MSFT 38138 521
36 C 1773741
39 C 37324707
39 S 99032745 AMZN 46079 3908
39 C 13629362
39 S 37055798 MSFT 21916 8753
39 B 56267909 AAPL 68125 9247
38 S 95759630 GOOG 53096 8266
38 B 42918170 AMZN 24747 6353
38 S 25239369 AMZN 82629 8100
39 B 74317702 MSFT 12062 3572
37 B 66266026 AMZN 87089 2070
38 B 8903901 MSFT 92789 808
37 C 66266026
39 B 41181898 GOOG 85576 8516
39 C 73220229
33 S 35108324 AMZN 32705 2820
37 B 24888633 AAPL 11177 6155
37 C 83226596
39 S 45581733 MSFT 40736 366
39 S 74115169 AAPL 32053 7891
36 S 6202257 AAPL 60438 4852
35 B 10089780 MSFT 11402 770
38 S 7109820 AMZN 90393 9479
39 B 83955708 GOOG 53918 2068
37 B 98642808 AAPL 66833 8222
38 C 25239369
39 S 26098450 MSFT 94848 8484
39 C 28743501
39 C 74317702
39 B 57754315 AMZN 94437 495
38 B 83589977 AAPL 71222 6508
35 B 73256518 AMZN 34995 2154
37 C 24888633
39 C 71610439
39 S 97070052 AMZN 48851 539
34 S 28912669 MSFT 61606 5842
39 C 13629362
37 C 24888633
39 S 8183190 MSFT 26499 1464
38 S 35153769 AAPL 34675 2767
39 C 13629362
38 B 38578802 MSFT 13865 8165
37 S 46727955 AMZN 23853 9573
35 S 97451215 AMZN 57275 9062
37 B 15973843 AMZN 86695 1270
38 B 42334171 AAPL 19155 825
39 C 2781313
36 B 525001 GOOG 56817 305
39 B 40308550 MSFT 68627 4160
36 C 1773741
39 C 73156997
38 S 196747 GOOG 51218 7488
39 S 29726847 MSFT 29350 6829
39 S 23110792 MSFT 64384 120
32 S 86944528 GOOG 5390 6584
39 S 18527504 MSFT 31638 6621
38 S 87561451 MSFT 45215 9595
39 B 97197584 AMZN 24333 7090
39 B 55504797 AMZN 42659 5321
36 B 30071221 GOOG 45288 860
39 S 71474747 GOOG 36645 6452
36 C 43500036
39 S 51910176 AMZN 36101 2893
39 B 27380524 AAPL 99737 716
38 S 39269125 AAPL 20948 7735
39 C 71527521
39 C 73156997
37 C 89544980
38 B 49197520 GOOG 77325 1276
39 S 30669245 AMZN 11454 421
38 S 86307110 AAPL 60968 3530
39 B 67979997 GOOG 19481 3671
39 C 29726847
39 B 19301662 MSFT 27378 4165
39 S 5430493 GOOG 53900 5479
39 C 40308550
39 S 2098954 GOOG 91151 9598
39 C 19205361
36 S 9099992 AAPL 83237 8772
38 B 90236373 MSFT 64473 4983
36 S 45278714 AMZN 95769 2008
39 C 45581733
34 B 1495105 AMZN 94977 9014
39 B 18125311 MSFT 82603 6929
39 C 68538484
38 S 2548281 AAPL 70497 4183
39 S 40297778 AAPL 82851 7709
35 C 6874966
38 B 96273170 MSFT 24288 3229
39 S 59055925 GOOG 45356 606
39 B 62617734 AAPL 47112 7652
37 C 46727955
39 B 67839515 AMZN 88201 2011
33 C 35108324
39 S 58492186 GOOG 82038 7613
36 C 43500036
38 S 61361723 MSFT 27680 4405
39 B 56872034 AMZN 66820 7659
39 S 91957228 AMZN 96867 1690
35 C 10089780
37 B 54980012 MSFT 50267 6190
39 B 28360599 MSFT 46808 8753
38 B 46333202 AMZN 2696 7783
39 C 27380524
39 S 86416783 AAPL 64403 5074
37 S 53476774 AAPL 77946 9245
39 S 13118146 AMZN 35798 6415
39 B 18131522 AMZN 66664 3043
36 C 9099992
33 S 68993110 AAPL 68602 8900
37 S 79891008 MSFT 84754 8473
38 S 58075623 MSFT 96933 4688
38 S 2762229 AAPL 6213 5414
35 C 73256518
38 S 30264964 AMZN 95257 8859
37 S 38300720 AAPL 2224 3924
38 S 58299007 MSFT 27384 9051
37 S 8189317 MSFT 99372 8925
37 S 52936586 AAPL 89435 4252
33 C 68993110
38 C 85180721
38 S 84974601 AMZN 86296 5082
37 S 1844922 GOOG 72405 1339
37 S 32905940 AMZN 10312 8326
36 C 525001
37 C 24888633
37 C 15973843
38 S 98758725 AAPL 88365 8154
38 C 196747
37 S 89324167 GOOG 72660 7629
38 C 95759630
37 S 20266280 AAPL 76237 6892
35 C 97451215
38 B 42053374 AAPL 77048 3046
36 C 525001
36 S 77724971 MSFT 79467 6923
38 B 14726322 AAPL 35060 7362
36 B 56493804 MSFT 13796 9147
37 S 93725059 MSFT 28430 3041
36 C 525001
38 B 46717657 AAPL 94205 8297
35 B 14247505 GOOG 65496 2120
38 C 8903901
38 B 78106571 GOOG 66371 5631
36 B 63034447 GOOG 19720 5187
38 B 44409930 AMZN 50798 2512
38 B 63187486 AMZN 23258 2244
37 B 60714342 AMZN 89828 3834
38 B 12510800 GOOG 29899 5124
38 B 24967332 GOOG 75584 337
37 C 69389474
37 S 80820831 AAPL 27285 2252
38 B 58803823 AAPL 52107 7400
38 S 18041605 MSFT 12537 2409
37 C 79891008
38 C 98758725
38 S 52242228 MSFT 36427 6467
38 S 25080016 AMZN 44480 7874
37 C 38300720
38 B 63658973 MSFT 46887 9194
37 C 54980012
38 B 99619006 AMZN 16132 7963
37 B 58164196 GOOG 24739 1920
37 S 49370478 AMZN 55064 4797
37 C 38300720
37 S 18356154 AAPL 3193 4465
38 C 42918170
38 S 82216815 MSFT 43329 3705
36 S 90269983 AMZN 27872 206
38 S 39760140 AMZN 68190 9604
36 S 601689 MSFT 74910 85
36 S 45633447 MSFT 68389 5324
38 B 50538786 GOOG 42972 5520
38 S 85806085 MSFT 54566 2225
38 C 18041605
38 B 1968173 AAPL 75521 9034
38 B 66828458 AAPL 68444 7860
36 S 18610599 AMZN 35761 9899
38 B 65951852 MSFT 90423 8630
38 B 89680782 GOOG 76773 1287
38 S 34803334 AAPL 46666 3821
38 C 52242228
38 C 49197520
38 C 85806085
38 B 22050307 AAPL 64634 4769
38 B 1168192 AMZN 11613 9910
38 C 66828458
38 C 44409930
38 C 24967332
34 C 1495105
38 S 50209935 AAPL 37454 4653
36 B 80966416 MSFT 50421 2398
38 C 22050307
36 S 16348302 AAPL 81491 8959
35 B 52419909 MSFT 82777 1901
38 C 83589977
38 C 84974601
38 C 50538786
37 C 68247028
38 C 25239369
36 C 56493804
37 B 77278720 GOOG 69164 9244
38 S 19127916 MSFT 22270 9708
35 B 20440239 AMZN 11796 1001
36 B 36898516 GOOG 16314 520
37 S 63498646 AMZN 30160 1272
38 S 91411286 AAPL 91829 3749
38 S 28771231 AAPL 74012 149
36 B 74590958 MSFT 48133 5417
36 C 45278714
37 B 80953239 MSFT 35333 3442
38 S 20792948 AAPL 9654 5119
37 C 1844922
38 B 18815848 MSFT 10933 9229
34 S 46947279 MSFT 62128 4812
38 B 91924809 AMZN 33036 8157
38 C 38578802
37 S 33445874 GOOG 75999 3082
38 C 46717657
38 S 17778804 AAPL 83099 790
38 B 38875500 AMZN 52346 8213
37 C 89544980
30 S 2943093 GOOG 73506 1429
36 S 9737555 AMZN 78239 6467
38 C 58299007
38 S 2996313 AMZN 54618 4510
38 S 18295502 GOOG 31633 6998
38 S 85935263 GOOG 65427 9493
36 B 98345637 GOOG 87448 6671
37 C 95728855
36 S 83306372 MSFT 3391 6993
37 S 24129437 MSFT 70965 3108
35 B 52040717 MSFT 9760 9379
