scripts/test_case14.txt
40
0 o
1 o
2 o
3 o
4 o
5 o
6 o
7 o
8 o
9 o
10 o
11 o
12 o
13 o
14 o
15 o
16 o
17 o
18 o
19 o
20 o
21 o
22 o
23 o
24 o
25 o
26 o
27 o
28 o
29 o
30 o
31 o
32 o
33 o
34 o
35 o
36 o
37 o
38 o
39 o
.
38 B 7689899 AAPL 15513 3518
39 B 92602387 GOOG 3746 6355
38 S 33956210 AAPL 2627 4395
39 C 92602387
39 B 53223146 MSFT 30156 3526
39 B 98322396 GOOG 3374 7699
39 C 98322396
39 C 92602387
36 S 66882926 AAPL 50058 6215
37 S 11350446 AMZN 58182 3016
36 C 66882926
39 C 53223146
38 S 30593766 AMZN 54246 960
39 S 67725316 GOOG 90747 5019
38 C 33956210
38 B 82565240 AMZN 99828 6954
39 B 11742042 GOOG 63145 747
39 C 67725316
39 C 53223146
39 S 63531932 MSFT 61189 3332
35 S 83719302 GOOG 74281 409
37 B 9018048 GOOG 1573 4583
38 B 87711486 AMZN 96043 7047
38 B 52743422 MSFT 49093 1388
37 B 6682457 GOOG 90654 8505
39 B 50751809 GOOG 2521 1664
39 C 63531932
39 S 4876592 MSFT 46268 7315
39 B 8964842 GOOG 25486 8450
39 B 58309712 GOOG 76159 831
39 C 11742042
37 C 9018048
39 S 84338092 AMZN 96837 5580
37 C 11350446
37 S 40450182 GOOG 98592 8397
39 B 71104152 AMZN 24980 2159
34 S 25651640 GOOG 9529 1944
39 C 50751809
39 C 58309712
39 S 23651385 AAPL 98646 8378
39 C 67725316
39 B 77224055 MSFT 32938 3713
39 C 53223146
39 C 98322396
36 C 66882926
38 B 98340554 AAPL 46146 4538
39 C 8964842
38 C 33956210
35 C 83719302
38 C 7689899
37 B 45155274 GOOG 21381 6788
39 S 84424351 AMZN 58200 6250
38 C 87711486
39 S 93560329 GOOG 24751 9924
39 C 77224055
38 B 91316158 GOOG 41197 2870
38 C 87711486
38 S 33022243 AAPL 67478 9182
39 B 8242634 MSFT 94995 1324
38 B 39787530 GOOG 30754 9636
39 C 67725316
37 S 36019200 AMZN 39120 6338
38 C 52743422
39 S 63633372 AAPL 40311 949
37 B 46127546 GOOG 87972 492
37 B 82665370 GOOG 78870 1266
39 C 23651385
38 S 58546231 AMZN 2505 4621
38 B 47527698 GOOG 32200 4497
39 B 87191411 GOOG 74416 7724
38 S 88500652 AMZN 23925 5812
39 S 84508767 AAPL 12998 2614
39 B 17814320 MSFT 69205 3642
39 B 18624322 AMZN 11994 8708
39 C 67725316
39 C 23651385
39 S 35953481 AAPL 81366 2162
37 B 77519732 MSFT 99120 6900
32 B 76365148 GOOG 29466 2989
38 S 4411498 MSFT 42173 9412
37 C 82665370
39 B 23995648 MSFT 14402 920
39 C 4876592
35 C 83719302
39 S 59056333 GOOG 44969 9759
39 S 20473556 MSFT 61956 8819
39 C 71104152
39 C 35953481
36 S 14171696 GOOG 57247 8236
39 B 58943195 GOOG 84789 4848
38 B 7112046 MSFT 54161 6480
39 B 38971452 AAPL 9361 3123
39 B 50126294 AAPL 12609 5660
38 C 91316158
38 B 77386800 AMZN 21277 7078
37 C 6682457
39 B 97104795 AMZN 89292 9150
39 S 15665065 MSFT 43639 9860
39 S 27332462 AAPL 72588 9834
37 C 45155274
38 S 32784425 AAPL 42171 7006
39 C 93560329
39 C 58943195
39 C 8964842
37 B 24871232 MSFT 28199 2102
35 S 6014797 AMZN 45014 607
36 S 32577083 AAPL 86655 3651
36 S 49852512 GOOG 15081 406
39 C 50126294
37 B 91648437 MSFT 98248 5755
38 B 49817618 AMZN 90636 669
39 S 53197276 AAPL 6957 6738
37 C 82665370
39 S 29838932 AMZN 38696 4773
39 S 61268727 AAPL 87499 3886
39 B 66496538 MSFT 75714 7524
39 B 78612086 MSFT 44901 866
38 C 39787530
37 B 21008774 AMZN 85853 7556
39 C 61268727
38 B 25939734 MSFT 57160 7811
39 B 75220628 GOOG 12653 4374
39 B 87340499 GOOG 97944 3872
38 C 32784425
39 C 84424351
38 S 18390818 AAPL 27512 9013
34 S 96558840 GOOG 3562 1107
39 S 86227170 MSFT 2747 6457
36 C 66882926
38 S 74380419 GOOG 94032 342
38 S 28353080 AAPL 55645 7302
39 S 52377433 AAPL 4382 7094
35 B 41490311 GOOG 10055 6058
39 C 93560329
39 S 45677699 AMZN 94562 4965
33 B 75833584 AAPL 17163 3888
39 S 15034605 AAPL 35827 836
39 B 68281032 MSFT 55246 4836
37 S 31565285 MSFT 34067 9508
34 C 25651640
38 B 16166655 MSFT 50947 6800
38 C 91316158
36 C 49852512
39 B 74507856 AMZN 35698 3254
38 C 32784425
38 S 71187223 GOOG 75864 5957
38 C 4411498
35 S 61926917 AMZN 58607 3168
38 B 37566574 MSFT 14957 8851
39 B 78234480 GOOG 53852 5802
38 S 19320254 MSFT 8515 5011
37 S 83524456 MSFT 33186 4046
38 C 91316158
39 S 46790365 GOOG 90379 7725
39 B 3702619 AMZN 5989 4296
39 C 27332462
38 C 74380419
39 S 47242668 AMZN 25283 7475
39 C 52377433
38 B 48447954 AMZN 51208 7924
38 B 48602175 MSFT 46674 4847
39 B 95209847 AAPL 59686 2671
39 S 61365635 AMZN 85495 2284
39 B 5441059 AAPL 71934 6542
39 C 50126294
37 B 36455921 GOOG 87734 2151
39 S 75272939 AMZN 51002 4540
38 C 4411498
39 B 68974997 MSFT 73553 6902
39 S 84051400 AMZN 22437 2423
39 S 9764469 MSFT 82506 3043
38 S 33790794 MSFT 74536 8180
39 C 3702619
39 S 38223039 MSFT 9250 7117
39 S 97850997 AMZN 30934 4610
38 C 7689899
39 S 79556767 AAPL 75054 3045
39 C 84424351
38 B 96393365 GOOG 19653 720
36 B 56823394 GOOG 77168 9489
39 C 5441059
39 C 68974997
39 C 20473556
39 C 78234480
39 S 78235891 AMZN 26023 7969
37 B 87531753 AMZN 1448 629
39 S 16098644 MSFT 72299 5552
38 S 55237691 MSFT 50838 2999
36 C 49852512
39 C 38223039
36 S 70486765 GOOG 61486 5385
38 C 48602175
38 B 22180172 GOOG 8501 9401
35 C 41490311
38 C 18390818
37 S 16686517 GOOG 77192 99
36 B 28050838 AMZN 59930 6331
38 C 39787530
38 B 21107199 AMZN 75170 9049
38 C 74380419
37 S 62576401 GOOG 10139 5977
36 C 28050838
38 S 33139162 AMZN 60639 1872
37 S 25913001 AMZN 65796 6379
38 C 16166655
38 B 80865605 GOOG 15767 8030
37 S 4252466 AMZN 40395 8733
38 C 82565240
35 B 11868782 GOOG 60267 8390
37 S 52106755 GOOG 75131 3221
38 B 28905401 AAPL 26365 9852
38 S 39557381 AMZN 71022 1069
38 B 90060433 GOOG 65240 9342
37 C 91648437
38 S 59209480 GOOG 25144 6907
34 C 96558840
38 S 35940251 AMZN 83273 2794
38 C 91316158
38 C 33790794
38 S 3423385 GOOG 86282 317
38 C 48447954
38 C 7112046
36 S 51256717 AAPL 54242 3801
38 S 7291356 AMZN 87438 5617
36 B 15138994 AAPL 59033 4666
38 B 75513510 MSFT 5892 253
36 B 59759305 MSFT 17051 4441
37 S 70304370 AAPL 62091 9233
38 S 85314288 GOOG 33393 8986
38 B 2349388 AMZN 41197 8883
37 S 13933534 GOOG 48229 7029
38 C 87711486
37 C 25913001
38 C 48602175
37 B 49861350 GOOG 97213 4938
38 S 36531284 GOOG 41189 7652
38 C 35940251
38 B 5392326 AAPL 38846 2199
38 S 23388712 MSFT 40722 9512
37 B 57477176 AMZN 75289 4690
38 C 33956210
31 B 98585135 AAPL 31753 4538
38 S 21310758 GOOG 80136 9342
38 S 29200908 GOOG 26866 6328
37 B 11331152 AAPL 99476 3512
37 B 86527034 AMZN 91298 2600
37 C 4252466
37 S 82046828 AMZN 66935 4674
36 B 38001808 AAPL 32675 6023
38 B 99706121 MSFT 7129 9004
37 S 70696777 MSFT 96907 9032
38 S 8617313 AAPL 83893 7900
36 S 91830860 MSFT 85102 6304
37 C 16686517
38 S 23554866 AMZN 86873 4824
38 S 57157747 MSFT 24164 997
37 C 16686517
37 B 14932920 AAPL 25373 629
38 C 21310758
38 B 79988209 MSFT 16660 4026
37 S 7274543 AMZN 33245 216
38 S 64469184 AAPL 57373 8367
38 B 87461228 MSFT 7461 2365
37 S 10291113 GOOG 1212 6277
38 S 36703333 MSFT 55144 9905
38 S 14535016 MSFT 45938 5455
35 B 15155623 AMZN 32202 1238
38 S 48747483 AMZN 87835 579
38 S 94600665 MSFT 81038 4156
36 C 15138994
38 S 34713787 AAPL 96479 7325
36 C 38001808
37 B 21759897 AAPL 52247 8861
38 B 62352700 MSFT 41846 7356
37 B 72422892 AMZN 93491 5798
34 B 254026 GOOG 48312 3660
38 C 34713787
37 B 383863 AMZN 89339 1149
38 S 55469995 GOOG 37737 4815
38 B 24015116 AAPL 80259 2451
38 B 641583 AAPL 22994 9089
37 B 91629341 MSFT 98994 6079
37 S 41503770 AMZN 44401 3242
36 B 58630872 MSFT 99390 5896
35 B 15448270 GOOG 9569 1619
38 B 7228909 GOOG 85192 1956
37 C 41503770
37 B 48377452 GOOG 55290 2470
36 B 14999736 GOOG 62363 5979
32 S 45160494 AMZN 67983 6292
37 C 82665370
35 B 21722662 AAPL 48250 7966
31 C 98585135
36 B 94162438 AMZN 25943 3312
37 B 80684305 AMZN 62035 956
37 S 4659095 MSFT 33769 8515
34 C 254026
36 S 81419293 AAPL 44550 5636
36 B 29737474 AAPL 55924 1849
35 B 65560725 AMZN 67562 6120
37 B 44833277 AAPL 9336 9957
37 B 61965183 MSFT 99294 5001
36 S 56888883 GOOG 54729 9918
34 C 96558840
37 S 84602469 GOOG 76039 6652
37 C 10291113
37 B 65559714 MSFT 96405 9295
37 C 77519732
37 C 13933534
35 C 15448270
37 S 80619738 MSFT 53340 5383
37 S 97103726 MSFT 10077 6486
34 S 83220560 AMZN 86411 8013
37 B 57535655 GOOG 87926 6311
37 B 1031899 MSFT 26532 3533
37 S 41728038 AMZN 82308 3414
37 B 9048455 GOOG 63551 2750
37 C 1031899
34 S 63470750 AAPL 91218 1912
37 C 13933534
